{"name": "Проверяем что упадет ошибка при попытки создания пользователя который уже есть в системе", "status": "passed", "start": 1703950448498, "stop": 1703950448780, "uuid": "5ebc9792-c2e1-40f1-95b2-0693ec0752ba", "historyId": "d9c898c8e89ddc4bb2129cff091ba9b9", "testCaseId": "d9c898c8e89ddc4bb2129cff091ba9b9", "fullName": "tests.test_create_user.TestCreateUser#test_check_create_identical_user", "labels": [{"name": "parentSuite", "value": "tests"}, {"name": "suite", "value": "test_create_user"}, {"name": "subSuite", "value": "TestCreateUser"}, {"name": "host", "value": "b-ibragimov"}, {"name": "thread", "value": "46910-MainThread"}, {"name": "framework", "value": "pytest"}, {"name": "language", "value": "cpython3"}, {"name": "package", "value": "tests.test_create_user"}]}